<?xml version="1.0" ?>
<!-- =================================================================================== -->
<!-- |    This document was autogenerated by xacro from my_robot.urdf.xacro            | -->
<!-- |    EDITING THIS FILE BY HAND IS NOT RECOMMENDED                                 | -->
<!-- =================================================================================== -->
<robot name="my_robot">

  <material name="blue">
    <color rgba="0 0 0.5 1"/>
  </material>
  <material name="grey">
    <color rgba="0.5 0.5 0.5 1"/>
  </material>
  <link name="base_footprint"/>
  <link name="base_link">
    <visual>
      <geometry>
        <box size="0.6 0.4 0.2"/>
      </geometry>
      <origin rpy="0 0 0" xyz="0 0 0.1"/>
      <material name="blue"/>
    </visual>
    <inertial>
      <origin rpy="0 0 0" xyz="0 0 0.1"/>
      <mass value="5.0"/>
      <inertia ixx="0.16666666666666669" ixy="0" ixz="0" iyy="0.21666666666666667" iyz="0" izz="0.08333333333333336"/>
    </inertial>
  </link>

  <link name="right_wheel_link">
    <visual>
      <geometry>
        <cylinder length="0.05" radius="0.1"/>
      </geometry>
      <origin rpy="1.5707963267948966 0 0" xyz="0 0 0"/>
      <material name="grey"/>
    </visual>
    <inertial>
      <origin rpy="1.5707963267948966 0 0" xyz="0 0 0"/>
      <mass value="1.0"/>
      <inertia ixx="0.002708333333333334" ixy="0" ixz="0" iyy="0.002708333333333334" iyz="0" izz="0.005000000000000001"/>
    </inertial>
  </link>

  <link name="left_wheel_link">
    <visual>
      <geometry>
        <cylinder length="0.05" radius="0.1"/>
      </geometry>
      <origin rpy="1.5707963267948966 0 0" xyz="0 0 0"/>
      <material name="grey"/>
    </visual>
    <inertial>
      <origin rpy="1.5707963267948966 0 0" xyz="0 0 0"/>
      <mass value="1.0"/>
      <inertia ixx="0.002708333333333334" ixy="0" ixz="0" iyy="0.002708333333333334" iyz="0" izz="0.005000000000000001"/>
    </inertial>
  </link>

  <link name="caster_wheel_link">
    <visual>
      <geometry>
        <sphere radius="0.05"/>
      </geometry>
      <origin rpy="0 0 0" xyz="0 0 0"/>
      <material name="grey"/>
    </visual>
    <inertial>
      <origin rpy="0 0 0" xyz="0 0 0"/>
      <mass value="0.5"/>
      <inertia ixx="0.0005000000000000001" ixy="0" ixz="0" iyy="0.0005000000000000001" iyz="0" izz="0.0005000000000000001"/>
    </inertial>
  </link>

  <joint name="base_joint" type="fixed">
    <parent link="base_footprint"/>
    <child link="base_link"/>
    <origin rpy="0 0 0" xyz="0 0 0.1"/>
  </joint>

  <joint name="base_right_wheel_joint" type="continuous">
    <parent link="base_link"/>
    <child link="right_wheel_link"/>
    <origin rpy="0 0 0" xyz="-0.15 -0.225 0"/>
    <axis xyz="0 1 0"/>
  </joint>

  <joint name="base_left_wheel_joint" type="continuous">
    <parent link="base_link"/>
    <child link="left_wheel_link"/>
    <origin rpy="0 0 0" xyz="-0.15 0.225 0"/>
    <axis xyz="0 1 0"/>
  </joint>

  <joint name="base_caster_wheel_joint" type="fixed">
    <parent link="base_link"/>
    <child link="caster_wheel_link"/>
    <origin rpy="0 0 0" xyz="0.19999999999999998 0 -0.05"/>
  </joint>

</robot>
